Unauthorized: /api/v1/clients/1/
C:\Users\Jean-Philippe\OpenClassRooms\P12\epicevents\settings.py changed, reloading.
Watching for file changes with StatReloader
C:\Users\Jean-Philippe\OpenClassRooms\P12\accounts\views.py changed, reloading.
Watching for file changes with StatReloader
Test
C:\Users\Jean-Philippe\OpenClassRooms\P12\accounts\views.py changed, reloading.
Watching for file changes with StatReloader
C:\Users\Jean-Philippe\OpenClassRooms\P12\epicevents\settings.py changed, reloading.
Watching for file changes with StatReloader
C:\Users\Jean-Philippe\OpenClassRooms\P12\epicevents\settings.py changed, reloading.
Watching for file changes with StatReloader
Watching for file changes with StatReloader
Not Found: /favicon.ico
No attribute called sales_contact
Traceback (most recent call last):
  File "C:\Users\Jean-Philippe\OpenClassRooms\P12\crm\permissions.py", line 28, in has_object_permission
    return obj.client.sales_contact == request.user
AttributeError: 'Client' object has no attribute 'client'
Forbidden: /api/v1/clients/1/
C:\Users\Jean-Philippe\OpenClassRooms\P12\accounts\permissions.py changed, reloading.
Watching for file changes with StatReloader
No attribute called sales_contact
Traceback (most recent call last):
  File "C:\Users\Jean-Philippe\OpenClassRooms\P12\crm\permissions.py", line 28, in has_object_permission
    return obj.client.sales_contact == request.user
AttributeError: 'Client' object has no attribute 'client'
Forbidden: /api/v1/clients/1/
C:\Users\Jean-Philippe\OpenClassRooms\P12\accounts\permissions.py changed, reloading.
Watching for file changes with StatReloader
No attribute called sales_contact
Traceback (most recent call last):
  File "C:\Users\Jean-Philippe\OpenClassRooms\P12\crm\permissions.py", line 28, in has_object_permission
    return obj.client.sales_contact == request.user
AttributeError: 'Client' object has no attribute 'client'
Forbidden: /api/v1/clients/1/
No attribute called sales_contact
Traceback (most recent call last):
  File "C:\Users\Jean-Philippe\OpenClassRooms\P12\crm\permissions.py", line 28, in has_object_permission
    return obj.client.sales_contact == request.user
AttributeError: 'Client' object has no attribute 'client'
Forbidden: /api/v1/clients/1/
C:\Users\Jean-Philippe\OpenClassRooms\P12\accounts\permissions.py changed, reloading.
Watching for file changes with StatReloader
C:\Users\Jean-Philippe\OpenClassRooms\P12\accounts\permissions.py changed, reloading.
Watching for file changes with StatReloader
C:\Users\Jean-Philippe\OpenClassRooms\P12\accounts\permissions.py changed, reloading.
Watching for file changes with StatReloader
C:\Users\Jean-Philippe\OpenClassRooms\P12\crm\views.py changed, reloading.
Watching for file changes with StatReloader
No attribute called sales_contact
Traceback (most recent call last):
  File "C:\Users\Jean-Philippe\OpenClassRooms\P12\crm\permissions.py", line 28, in has_object_permission
    return obj.client.sales_contact == request.user
AttributeError: 'Client' object has no attribute 'client'
No attribute called sales_contact
Traceback (most recent call last):
  File "C:\Users\Jean-Philippe\OpenClassRooms\P12\crm\permissions.py", line 28, in has_object_permission
    return obj.client.sales_contact == request.user
AttributeError: 'Client' object has no attribute 'client'
No attribute called sales_contact
Traceback (most recent call last):
  File "C:\Users\Jean-Philippe\OpenClassRooms\P12\crm\permissions.py", line 28, in has_object_permission
    return obj.client.sales_contact == request.user
AttributeError: 'Client' object has no attribute 'client'
No attribute called sales_contact
Traceback (most recent call last):
  File "C:\Users\Jean-Philippe\OpenClassRooms\P12\crm\permissions.py", line 28, in has_object_permission
    return obj.client.sales_contact == request.user
AttributeError: 'Client' object has no attribute 'client'
No attribute called sales_contact
Traceback (most recent call last):
  File "C:\Users\Jean-Philippe\OpenClassRooms\P12\crm\permissions.py", line 28, in has_object_permission
    return obj.client.sales_contact == request.user
AttributeError: 'Client' object has no attribute 'client'
No attribute called sales_contact
Traceback (most recent call last):
  File "C:\Users\Jean-Philippe\OpenClassRooms\P12\crm\permissions.py", line 28, in has_object_permission
    return obj.client.sales_contact == request.user
AttributeError: 'Client' object has no attribute 'client'
C:\Users\Jean-Philippe\OpenClassRooms\P12\crm\views.py changed, reloading.
Watching for file changes with StatReloader
No attribute called sales_contact
Traceback (most recent call last):
  File "C:\Users\Jean-Philippe\OpenClassRooms\P12\crm\permissions.py", line 28, in has_object_permission
    return obj.client.sales_contact == request.user
AttributeError: 'Client' object has no attribute 'client'
No attribute called sales_contact
Traceback (most recent call last):
  File "C:\Users\Jean-Philippe\OpenClassRooms\P12\crm\permissions.py", line 28, in has_object_permission
    return obj.client.sales_contact == request.user
AttributeError: 'Client' object has no attribute 'client'
No attribute called sales_contact
Traceback (most recent call last):
  File "C:\Users\Jean-Philippe\OpenClassRooms\P12\crm\permissions.py", line 28, in has_object_permission
    return obj.client.sales_contact == request.user
AttributeError: 'Client' object has no attribute 'client'
No attribute called sales_contact
Traceback (most recent call last):
  File "C:\Users\Jean-Philippe\OpenClassRooms\P12\crm\permissions.py", line 28, in has_object_permission
    return obj.client.sales_contact == request.user
AttributeError: 'Client' object has no attribute 'client'
No attribute called sales_contact
Traceback (most recent call last):
  File "C:\Users\Jean-Philippe\OpenClassRooms\P12\crm\permissions.py", line 28, in has_object_permission
    return obj.client.sales_contact == request.user
AttributeError: 'Client' object has no attribute 'client'
No attribute called sales_contact
Traceback (most recent call last):
  File "C:\Users\Jean-Philippe\OpenClassRooms\P12\crm\permissions.py", line 28, in has_object_permission
    return obj.client.sales_contact == request.user
AttributeError: 'Client' object has no attribute 'client'
Unauthorized: /api/v1/clients/
Unauthorized: /api/login/refresh/
Unauthorized: /api/v1/clients/
Unauthorized: /api/v1/clients/1/
No attribute called sales_contact
Traceback (most recent call last):
  File "C:\Users\Jean-Philippe\OpenClassRooms\P12\crm\permissions.py", line 28, in has_object_permission
    return obj.client.sales_contact == request.user
AttributeError: 'Client' object has no attribute 'client'
Internal Server Error: /api/v1/clients/1/
Traceback (most recent call last):
  File "C:\Users\Jean-Philippe\OpenClassRooms\P12\env\lib\site-packages\django\db\backends\utils.py", line 85, in _execute
    return self.cursor.execute(sql, params)
psycopg2.errors.ForeignKeyViolation: ERREUR:  UPDATE ou DELETE sur la table « crm_client » viole la contrainte de clé étrangère « crm_contract_client_id_a6b28105_fk_crm_client_id » de la table « crm_contract »
DETAIL:  La clé (id)=(1) est toujours référencée à partir de la table « crm_contract ».


The above exception was the direct cause of the following exception:

Traceback (most recent call last):
  File "C:\Users\Jean-Philippe\OpenClassRooms\P12\env\lib\site-packages\django\core\handlers\exception.py", line 47, in inner
    response = get_response(request)
  File "C:\Users\Jean-Philippe\OpenClassRooms\P12\env\lib\site-packages\django\core\handlers\base.py", line 181, in _get_response
    response = wrapped_callback(request, *callback_args, **callback_kwargs)
  File "C:\Users\Jean-Philippe\OpenClassRooms\P12\env\lib\site-packages\django\views\decorators\csrf.py", line 54, in wrapped_view
    return view_func(*args, **kwargs)
  File "C:\Users\Jean-Philippe\OpenClassRooms\P12\env\lib\site-packages\rest_framework\viewsets.py", line 125, in view
    return self.dispatch(request, *args, **kwargs)
  File "C:\Users\Jean-Philippe\OpenClassRooms\P12\env\lib\site-packages\rest_framework\views.py", line 509, in dispatch
    response = self.handle_exception(exc)
  File "C:\Users\Jean-Philippe\OpenClassRooms\P12\env\lib\site-packages\rest_framework\views.py", line 469, in handle_exception
    self.raise_uncaught_exception(exc)
  File "C:\Users\Jean-Philippe\OpenClassRooms\P12\env\lib\site-packages\rest_framework\views.py", line 480, in raise_uncaught_exception
    raise exc
  File "C:\Users\Jean-Philippe\OpenClassRooms\P12\env\lib\site-packages\rest_framework\views.py", line 506, in dispatch
    response = handler(request, *args, **kwargs)
  File "C:\Users\Jean-Philippe\OpenClassRooms\P12\env\lib\site-packages\rest_framework\mixins.py", line 91, in destroy
    self.perform_destroy(instance)
  File "C:\Users\Jean-Philippe\OpenClassRooms\P12\env\lib\site-packages\rest_framework\mixins.py", line 95, in perform_destroy
    instance.delete()
  File "C:\Users\Jean-Philippe\OpenClassRooms\P12\env\lib\site-packages\django\db\models\base.py", line 971, in delete
    return collector.delete()
  File "C:\Users\Jean-Philippe\OpenClassRooms\P12\env\lib\site-packages\django\db\models\deletion.py", line 398, in delete
    count = sql.DeleteQuery(model).delete_batch([instance.pk], self.using)
  File "C:\Users\Jean-Philippe\OpenClassRooms\P12\env\lib\site-packages\django\db\models\sql\subqueries.py", line 44, in delete_batch
    num_deleted += self.do_query(self.get_meta().db_table, self.where, using=using)
  File "C:\Users\Jean-Philippe\OpenClassRooms\P12\env\lib\site-packages\django\db\models\sql\subqueries.py", line 22, in do_query
    cursor = self.get_compiler(using).execute_sql(CURSOR)
  File "C:\Users\Jean-Philippe\OpenClassRooms\P12\env\lib\site-packages\django\db\models\sql\compiler.py", line 1202, in execute_sql
    cursor.execute(sql, params)
  File "C:\Users\Jean-Philippe\OpenClassRooms\P12\env\lib\site-packages\django\db\backends\utils.py", line 99, in execute
    return super().execute(sql, params)
  File "C:\Users\Jean-Philippe\OpenClassRooms\P12\env\lib\site-packages\django\db\backends\utils.py", line 67, in execute
    return self._execute_with_wrappers(sql, params, many=False, executor=self._execute)
  File "C:\Users\Jean-Philippe\OpenClassRooms\P12\env\lib\site-packages\django\db\backends\utils.py", line 76, in _execute_with_wrappers
    return executor(sql, params, many, context)
  File "C:\Users\Jean-Philippe\OpenClassRooms\P12\env\lib\site-packages\django\db\backends\utils.py", line 80, in _execute
    with self.db.wrap_database_errors:
  File "C:\Users\Jean-Philippe\OpenClassRooms\P12\env\lib\site-packages\django\db\utils.py", line 90, in __exit__
    raise dj_exc_value.with_traceback(traceback) from exc_value
  File "C:\Users\Jean-Philippe\OpenClassRooms\P12\env\lib\site-packages\django\db\backends\utils.py", line 85, in _execute
    return self.cursor.execute(sql, params)
django.db.utils.IntegrityError: ERREUR:  UPDATE ou DELETE sur la table « crm_client » viole la contrainte de clé étrangère « crm_contract_client_id_a6b28105_fk_crm_client_id » de la table « crm_contract »
DETAIL:  La clé (id)=(1) est toujours référencée à partir de la table « crm_contract ».

C:\Users\Jean-Philippe\OpenClassRooms\P12\crm\models.py changed, reloading.
Watching for file changes with StatReloader
C:\Users\Jean-Philippe\OpenClassRooms\P12\crm\models.py changed, reloading.
Watching for file changes with StatReloader
C:\Users\Jean-Philippe\OpenClassRooms\P12\crm\models.py changed, reloading.
Watching for file changes with StatReloader
C:\Users\Jean-Philippe\OpenClassRooms\P12\crm\models.py changed, reloading.
Watching for file changes with StatReloader
Watching for file changes with StatReloader
No attribute called sales_contact
Traceback (most recent call last):
  File "C:\Users\Jean-Philippe\OpenClassRooms\P12\crm\permissions.py", line 28, in has_object_permission
    return obj.client.sales_contact == request.user
AttributeError: 'Client' object has no attribute 'client'
Unauthorized: /api/v1/users/
Unauthorized: /api/v1/users/3/
No attribute called sales_contact
Traceback (most recent call last):
  File "C:\Users\Jean-Philippe\OpenClassRooms\P12\crm\permissions.py", line 28, in has_object_permission
    return obj.client.sales_contact == request.user
AttributeError: 'NoneType' object has no attribute 'sales_contact'
No attribute called sales_contact
Traceback (most recent call last):
  File "C:\Users\Jean-Philippe\OpenClassRooms\P12\crm\permissions.py", line 28, in has_object_permission
    return obj.client.sales_contact == request.user
AttributeError: 'NoneType' object has no attribute 'sales_contact'
No attribute called sales_contact
Traceback (most recent call last):
  File "C:\Users\Jean-Philippe\OpenClassRooms\P12\crm\permissions.py", line 28, in has_object_permission
    return obj.client.sales_contact == request.user
AttributeError: 'NoneType' object has no attribute 'sales_contact'
No attribute called sales_contact
Traceback (most recent call last):
  File "C:\Users\Jean-Philippe\OpenClassRooms\P12\crm\permissions.py", line 28, in has_object_permission
    return obj.client.sales_contact == request.user
AttributeError: 'NoneType' object has no attribute 'sales_contact'
No attribute called sales_contact
Traceback (most recent call last):
  File "C:\Users\Jean-Philippe\OpenClassRooms\P12\crm\permissions.py", line 28, in has_object_permission
    return obj.client.sales_contact == request.user
AttributeError: 'NoneType' object has no attribute 'sales_contact'
Internal Server Error: /api/v1/contracts/2
Traceback (most recent call last):
  File "C:\Users\Jean-Philippe\OpenClassRooms\P12\env\lib\site-packages\django\core\handlers\exception.py", line 47, in inner
    response = get_response(request)
  File "C:\Users\Jean-Philippe\OpenClassRooms\P12\env\lib\site-packages\django\utils\deprecation.py", line 125, in __call__
    response = self.process_request(request)
  File "C:\Users\Jean-Philippe\OpenClassRooms\P12\env\lib\site-packages\django\middleware\common.py", line 54, in process_request
    path = self.get_full_path_with_slash(request)
  File "C:\Users\Jean-Philippe\OpenClassRooms\P12\env\lib\site-packages\django\middleware\common.py", line 88, in get_full_path_with_slash
    raise RuntimeError(
RuntimeError: You called this URL via PUT, but the URL doesn't end in a slash and you have APPEND_SLASH set. Django can't redirect to the slash URL while maintaining PUT data. Change your form to point to 127.0.0.1:8000/api/v1/contracts/2/?sales_contact=3&client=2&contract_status=NOT%20SIGNED (note the trailing slash), or set APPEND_SLASH=False in your Django settings.
No attribute called sales_contact
Traceback (most recent call last):
  File "C:\Users\Jean-Philippe\OpenClassRooms\P12\crm\permissions.py", line 28, in has_object_permission
    return obj.client.sales_contact == request.user
AttributeError: 'NoneType' object has no attribute 'sales_contact'
No attribute called sales_contact
Traceback (most recent call last):
  File "C:\Users\Jean-Philippe\OpenClassRooms\P12\crm\permissions.py", line 28, in has_object_permission
    return obj.client.sales_contact == request.user
AttributeError: 'NoneType' object has no attribute 'sales_contact'
C:\Users\Jean-Philippe\OpenClassRooms\P12\crm\models.py changed, reloading.
Watching for file changes with StatReloader
Watching for file changes with StatReloader
No attribute called sales_contact
Traceback (most recent call last):
  File "C:\Users\Jean-Philippe\OpenClassRooms\P12\crm\permissions.py", line 28, in has_object_permission
    return obj.client.sales_contact == request.user
AttributeError: 'NoneType' object has no attribute 'sales_contact'
No attribute called sales_contact
Traceback (most recent call last):
  File "C:\Users\Jean-Philippe\OpenClassRooms\P12\crm\permissions.py", line 28, in has_object_permission
    return obj.client.sales_contact == request.user
AttributeError: 'NoneType' object has no attribute 'sales_contact'
No attribute called sales_contact
Traceback (most recent call last):
  File "C:\Users\Jean-Philippe\OpenClassRooms\P12\crm\permissions.py", line 28, in has_object_permission
    return obj.client.sales_contact == request.user
AttributeError: 'NoneType' object has no attribute 'sales_contact'
No attribute called sales_contact
Traceback (most recent call last):
  File "C:\Users\Jean-Philippe\OpenClassRooms\P12\crm\permissions.py", line 28, in has_object_permission
    return obj.client.sales_contact == request.user
AttributeError: 'NoneType' object has no attribute 'sales_contact'
Bad Request: /api/v1/contracts/2/
Unauthorized: /api/v1/events/
No attribute called sales_contact
Traceback (most recent call last):
  File "C:\Users\Jean-Philippe\OpenClassRooms\P12\crm\permissions.py", line 28, in has_object_permission
    return obj.client.sales_contact == request.user
AttributeError: 'NoneType' object has no attribute 'sales_contact'
Internal Server Error: /api/v1/events/1/
Traceback (most recent call last):
  File "C:\Users\Jean-Philippe\OpenClassRooms\P12\crm\permissions.py", line 28, in has_object_permission
    return obj.client.sales_contact == request.user
AttributeError: 'NoneType' object has no attribute 'sales_contact'

During handling of the above exception, another exception occurred:

Traceback (most recent call last):
  File "C:\Users\Jean-Philippe\OpenClassRooms\P12\env\lib\site-packages\django\core\handlers\exception.py", line 47, in inner
    response = get_response(request)
  File "C:\Users\Jean-Philippe\OpenClassRooms\P12\env\lib\site-packages\django\core\handlers\base.py", line 181, in _get_response
    response = wrapped_callback(request, *callback_args, **callback_kwargs)
  File "C:\Users\Jean-Philippe\OpenClassRooms\P12\env\lib\site-packages\django\views\decorators\csrf.py", line 54, in wrapped_view
    return view_func(*args, **kwargs)
  File "C:\Users\Jean-Philippe\OpenClassRooms\P12\env\lib\site-packages\rest_framework\viewsets.py", line 125, in view
    return self.dispatch(request, *args, **kwargs)
  File "C:\Users\Jean-Philippe\OpenClassRooms\P12\env\lib\site-packages\rest_framework\views.py", line 509, in dispatch
    response = self.handle_exception(exc)
  File "C:\Users\Jean-Philippe\OpenClassRooms\P12\env\lib\site-packages\rest_framework\views.py", line 469, in handle_exception
    self.raise_uncaught_exception(exc)
  File "C:\Users\Jean-Philippe\OpenClassRooms\P12\env\lib\site-packages\rest_framework\views.py", line 480, in raise_uncaught_exception
    raise exc
  File "C:\Users\Jean-Philippe\OpenClassRooms\P12\env\lib\site-packages\rest_framework\views.py", line 506, in dispatch
    response = handler(request, *args, **kwargs)
  File "C:\Users\Jean-Philippe\OpenClassRooms\P12\env\lib\site-packages\rest_framework\mixins.py", line 65, in update
    instance = self.get_object()
  File "C:\Users\Jean-Philippe\OpenClassRooms\P12\env\lib\site-packages\rest_framework\generics.py", line 99, in get_object
    self.check_object_permissions(self.request, obj)
  File "C:\Users\Jean-Philippe\OpenClassRooms\P12\env\lib\site-packages\rest_framework\views.py", line 345, in check_object_permissions
    if not permission.has_object_permission(request, self, obj):
  File "C:\Users\Jean-Philippe\OpenClassRooms\P12\env\lib\site-packages\rest_framework\permissions.py", line 81, in has_object_permission
    self.op1.has_object_permission(request, view, obj) or
  File "C:\Users\Jean-Philippe\OpenClassRooms\P12\env\lib\site-packages\rest_framework\permissions.py", line 81, in has_object_permission
    self.op1.has_object_permission(request, view, obj) or
  File "C:\Users\Jean-Philippe\OpenClassRooms\P12\crm\permissions.py", line 31, in has_object_permission
    return obj.sales_contact == request.user
AttributeError: 'Event' object has no attribute 'sales_contact'
No attribute called sales_contact
Traceback (most recent call last):
  File "C:\Users\Jean-Philippe\OpenClassRooms\P12\crm\permissions.py", line 28, in has_object_permission
    return obj.client.sales_contact == request.user
AttributeError: 'NoneType' object has no attribute 'sales_contact'
Internal Server Error: /api/v1/events/1/
Traceback (most recent call last):
  File "C:\Users\Jean-Philippe\OpenClassRooms\P12\crm\permissions.py", line 28, in has_object_permission
    return obj.client.sales_contact == request.user
AttributeError: 'NoneType' object has no attribute 'sales_contact'

During handling of the above exception, another exception occurred:

Traceback (most recent call last):
  File "C:\Users\Jean-Philippe\OpenClassRooms\P12\env\lib\site-packages\django\core\handlers\exception.py", line 47, in inner
    response = get_response(request)
  File "C:\Users\Jean-Philippe\OpenClassRooms\P12\env\lib\site-packages\django\core\handlers\base.py", line 181, in _get_response
    response = wrapped_callback(request, *callback_args, **callback_kwargs)
  File "C:\Users\Jean-Philippe\OpenClassRooms\P12\env\lib\site-packages\django\views\decorators\csrf.py", line 54, in wrapped_view
    return view_func(*args, **kwargs)
  File "C:\Users\Jean-Philippe\OpenClassRooms\P12\env\lib\site-packages\rest_framework\viewsets.py", line 125, in view
    return self.dispatch(request, *args, **kwargs)
  File "C:\Users\Jean-Philippe\OpenClassRooms\P12\env\lib\site-packages\rest_framework\views.py", line 509, in dispatch
    response = self.handle_exception(exc)
  File "C:\Users\Jean-Philippe\OpenClassRooms\P12\env\lib\site-packages\rest_framework\views.py", line 469, in handle_exception
    self.raise_uncaught_exception(exc)
  File "C:\Users\Jean-Philippe\OpenClassRooms\P12\env\lib\site-packages\rest_framework\views.py", line 480, in raise_uncaught_exception
    raise exc
  File "C:\Users\Jean-Philippe\OpenClassRooms\P12\env\lib\site-packages\rest_framework\views.py", line 506, in dispatch
    response = handler(request, *args, **kwargs)
  File "C:\Users\Jean-Philippe\OpenClassRooms\P12\env\lib\site-packages\rest_framework\mixins.py", line 65, in update
    instance = self.get_object()
  File "C:\Users\Jean-Philippe\OpenClassRooms\P12\env\lib\site-packages\rest_framework\generics.py", line 99, in get_object
    self.check_object_permissions(self.request, obj)
  File "C:\Users\Jean-Philippe\OpenClassRooms\P12\env\lib\site-packages\rest_framework\views.py", line 345, in check_object_permissions
    if not permission.has_object_permission(request, self, obj):
  File "C:\Users\Jean-Philippe\OpenClassRooms\P12\env\lib\site-packages\rest_framework\permissions.py", line 81, in has_object_permission
    self.op1.has_object_permission(request, view, obj) or
  File "C:\Users\Jean-Philippe\OpenClassRooms\P12\env\lib\site-packages\rest_framework\permissions.py", line 81, in has_object_permission
    self.op1.has_object_permission(request, view, obj) or
  File "C:\Users\Jean-Philippe\OpenClassRooms\P12\crm\permissions.py", line 31, in has_object_permission
    return obj.sales_contact == request.user
AttributeError: 'Event' object has no attribute 'sales_contact'
C:\Users\Jean-Philippe\OpenClassRooms\P12\crm\models.py changed, reloading.
Watching for file changes with StatReloader
C:\Users\Jean-Philippe\OpenClassRooms\P12\crm\models.py changed, reloading.
Watching for file changes with StatReloader
C:\Users\Jean-Philippe\OpenClassRooms\P12\crm\models.py changed, reloading.
Watching for file changes with StatReloader
C:\Users\Jean-Philippe\OpenClassRooms\P12\crm\models.py changed, reloading.
Watching for file changes with StatReloader
Watching for file changes with StatReloader
Bad Request: /api/v1/events/1/
Watching for file changes with StatReloader
C:\Users\Jean-Philippe\OpenClassRooms\P12\crm\permissions.py changed, reloading.
Watching for file changes with StatReloader
